Workbook

Sheet Inputs
B2: Offshore discount | C2: 0.5
A4: x | B4: Role | C4: Total | D4: US count | E4: US salary | F4: Offshore count | G4: Offshore salary | H4: Hours per week | I4: Weighted average salary
B5: SSR | C5: =COUNTA(_xlfn.UNIQUE(SSRs!$A$2:$A$3338)) -> 188 | D5: =C5-F5 -> 188 | E5: 60000 | G5: =E5*$C$2 -> 30000 | H5: 40 | I5: =(E5*D5+G5*F5)/C5 -> 60000
B6: TM | C6: =COUNTA(_xlfn.UNIQUE(TMs!$A$2:$A$11972)) -> 139 | D6: =C6-F6 -> 139 | E6: 60000 | G6: =E6*$C$2 -> 30000 | H6: 40 | I6: =(E6*D6+G6*F6)/C6 -> 60000
B7: MTS Pod | C7: =COUNTA(_xlfn.UNIQUE('MTS Pod'!$A$2:$A$1481)) -> 73 | D7: =C7-F7 -> 57 | E7: 60000 | F7: {=COUNTA(_xlfn.UNIQUE(_xlfn._xlws.FILTER('MTS Pod'!$A$2:$A$1481,'MTS Pod'!$E$2:$E$1481="Pod_Ovs")))} -> 16 | G7: =E7*$C$2 -> 30000 | H7: 40 | I7: =(E7*D7+G7*F7)/C7 -> 53424.658
B8: R+R Pod | C8: =COUNTA(_xlfn.UNIQUE('RnR Pod'!$A$2:$A$961)) -> 48 | D8: =C8-F8 -> 43 | E8: 60000 | F8: {=COUNTA(_xlfn.UNIQUE(_xlfn._xlws.FILTER('RnR Pod'!$A$2:$A$961,'RnR Pod'!$F$2:$F$961="Pod_Ovs")))} -> 5 | G8: =E8*$C$2 -> 30000 | H8: 40 | I8: =(E8*D8+G8*F8)/C8 -> 56875
B9: Customer Care | C9: =SUM('Customer Service'!$V$13:$V$15) -> 51 | D9: =C9-F9 -> 21 | E9: 60000 | F9: ='Customer Service'!V15 -> 30 | G9: =E9*$C$2 -> 30000 | H9: 40 | I9: =(E9*D9+G9*F9)/C9 -> 42352.941
B10: Purchasing | C10: 50 | E10: 60000 | H10: 40
B11: Fin. Services | C11: 75 | E11: 60000 | H11: 40

Sheet Summary
B2: Role | C2: Total hours per week | D2: Hours saved per week (low-end) | E2: Hours saved per week (high-end) | F2: Efficiency impact on total hours (low-end) | G2: Efficiency impact on total hours (high-end) | H2: Baseline | I2: $ impact (low-end) | J2: $ impact (high-end) | K2: $ impact (average)
B3: SSR | C3: =_xlfn.XLOOKUP($B3,Inputs!$B$5:$B$9,Inputs!$H$5:$H$9) -> 40 | D3: =SUMIFS('Individual Initiative Impact'!M$4:M$95,'Individual Initiative Impact'!$B$4:$B$95,$B3) -> 9.8181818 | E3: =SUMIFS('Individual Initiative Impact'!N$4:N$95,'Individual Initiative Impact'!$B$4:$B$95,$B3) -> 17.545455 | F3: =D3/$C3 -> 0.24545455 | G3: =E3/$C3 -> 0.43863636 | H3: =Inputs!I5*Inputs!C5 -> 11280000 | I3: =SUMIFS('Individual Initiative Impact'!Q$4:Q$95,'Individual Initiative Impact'!$B$4:$B$95,$B3) -> 2768727.3 | J3: =SUMIFS('Individual Initiative Impact'!R$4:R$95,'Individual Initiative Impact'!$B$4:$B$95,$B3) -> 4947818.2 | K3: =AVERAGE(I3:J3) -> 3858272.7
B4: TM | C4: =_xlfn.XLOOKUP($B4,Inputs!$B$5:$B$9,Inputs!$H$5:$H$9) -> 40 | D4: =SUMIFS('Individual Initiative Impact'!M$4:M$95,'Individual Initiative Impact'!$B$4:$B$95,$B4) -> 15.237209 | E4: =SUMIFS('Individual Initiative Impact'!N$4:N$95,'Individual Initiative Impact'!$B$4:$B$95,$B4) -> 25.395349 | F4: =D4/$C4 -> 0.38093023 | G4: =E4/$C4 -> 0.63488372 | H4: =Inputs!I6*Inputs!C6 -> 8340000 | I4: =SUMIFS('Individual Initiative Impact'!Q$4:Q$95,'Individual Initiative Impact'!$B$4:$B$95,$B4) -> 3176958.1 | J4: =SUMIFS('Individual Initiative Impact'!R$4:R$95,'Individual Initiative Impact'!$B$4:$B$95,$B4) -> 5294930.2 | K4: =AVERAGE(I4:J4) -> 4235944.2
B5: MTS Pod | C5: =_xlfn.XLOOKUP($B5,Inputs!$B$5:$B$9,Inputs!$H$5:$H$9) -> 40 | D5: =SUMIFS('Individual Initiative Impact'!M$4:M$95,'Individual Initiative Impact'!$B$4:$B$95,$B5) -> 17.821782 | E5: =SUMIFS('Individual Initiative Impact'!N$4:N$95,'Individual Initiative Impact'!$B$4:$B$95,$B5) -> 25.108911 | F5: =D5/$C5 -> 0.44554455 | G5: =E5/$C5 -> 0.62772277 | H5: =Inputs!I7*Inputs!C7 -> 3900000 | I5: =SUMIFS('Individual Initiative Impact'!Q$4:Q$95,'Individual Initiative Impact'!$B$4:$B$95,$B5) -> 1737623.8 | J5: =SUMIFS('Individual Initiative Impact'!R$4:R$95,'Individual Initiative Impact'!$B$4:$B$95,$B5) -> 2448118.8 | K5: =AVERAGE(I5:J5) -> 2092871.3
B6: R+R Pod | C6: =_xlfn.XLOOKUP($B6,Inputs!$B$5:$B$9,Inputs!$H$5:$H$9) -> 40 | D6: =SUMIFS('Individual Initiative Impact'!M$4:M$95,'Individual Initiative Impact'!$B$4:$B$95,$B6) -> 11.612245 | E6: =SUMIFS('Individual Initiative Impact'!N$4:N$95,'Individual Initiative Impact'!$B$4:$B$95,$B6) -> 17.326531 | F6: =D6/$C6 -> 0.29030612 | G6: =E6/$C6 -> 0.43316327 | H6: =Inputs!I8*Inputs!C8 -> 2730000 | I6: =SUMIFS('Individual Initiative Impact'!Q$4:Q$95,'Individual Initiative Impact'!$B$4:$B$95,$B6) -> 792535.71 | J6: =SUMIFS('Individual Initiative Impact'!R$4:R$95,'Individual Initiative Impact'!$B$4:$B$95,$B6) -> 1182535.7 | K6: =AVERAGE(I6:J6) -> 987535.71
B7: Customer Care | C7: =_xlfn.XLOOKUP($B7,Inputs!$B$5:$B$9,Inputs!$H$5:$H$9) -> 40 | D7: =SUMIFS('Individual Initiative Impact'!M$4:M$95,'Individual Initiative Impact'!$B$4:$B$95,$B7) -> 13.380676 | E7: =SUMIFS('Individual Initiative Impact'!N$4:N$95,'Individual Initiative Impact'!$B$4:$B$95,$B7) -> 20.585655 | F7: =D7/$C7 -> 0.33451689 | G7: =E7/$C7 -> 0.51464138 | H7: =Inputs!I9*Inputs!C9 -> 2160000 | I7: =SUMIFS('Individual Initiative Impact'!Q$4:Q$95,'Individual Initiative Impact'!$B$4:$B$95,$B7) -> 722556.49 | J7: =SUMIFS('Individual Initiative Impact'!R$4:R$95,'Individual Initiative Impact'!$B$4:$B$95,$B7) -> 1111625.4 | K7: =AVERAGE(I7:J7) -> 917090.93
B9: Total | C9: =SUMPRODUCT(C3:C7,Inputs!$C$5:$C$9)/SUM(Inputs!$C$5:$C$9) -> 40 | D9: =SUMPRODUCT(D3:D7,Inputs!$C$5:$C$9)/SUM(Inputs!$C$5:$C$9) -> 13.035236 | E9: =SUMPRODUCT(E3:E7,Inputs!$C$5:$C$9)/SUM(Inputs!$C$5:$C$9) -> 21.128239 | F9: =D9/$C9 -> 0.32588089 | G9: =E9/$C9 -> 0.52820598 | H9: =SUM(H3:H7) -> 28410000 | I9: =SUM(I3:I7) -> 9198401.4 | J9: =SUM(J3:J7) -> 14985028 | K9: =SUM(K3:K7) -> 12091715

Sheet Individual Initiative Impact
B3: Role | C3: FTEs for ROLE | D3: Cost per year for ROLE | E3: Total hours per week for ROLE | F3: Archetype | G3: Category of opportunity | H3: Opportunity description | I3: Current time spent on activity category (%) | J3: Current time spent on activity archetype (hrs per week) | K3: Efficiency gained on activity archetype % (low-end) | L3: Efficiency gained on activity archetype % (high-end) | M3: Hours saved (low-end) | N3: Hours saved (high-end) | O3: Efficiency gained % on total workweek (low-end) | P3: Efficiency gained % on total workweek (high-end) | Q3: $ impact (low-end) | R3: $ impact (high-end)
B4: R+R Pod | C4: =_xlfn.XLOOKUP($B4,Inputs!$B$5:$B$9,Inputs!$C$5:$C$9) -> 48 | D4: =_xlfn.XLOOKUP($B4,Inputs!$B$5:$B$9,Inputs!I$5:I$9) -> 56875 | E4: =_xlfn.XLOOKUP($B4,Inputs!$B$5:$B$9,Inputs!H$5:H$9) -> 40 | F4: Communication & coordination | G4: Process | H4: Standardize and schedule reminder templates for vendor follow-ups (e.g., pending return authorization, missing info) | I4: {=_xlfn.IFNA(_xlfn.XLOOKUP(B4&F4,'Activity by Category'!$B$4:$B$99&'Activity by Category'!$C$4:$C$99,'Activity by Category'!$E$4:$E$99)/100,1)} -> 0.20408163 | J4: =I4*_xlfn.XLOOKUP($B4,Inputs!$B$5:$B$9,Inputs!$H$5:$H$9) -> 8.1632653 | K4: 0.04 | L4: 0.06 | M4: =$J4*K4 -> 0.32653061 | N4: =$J4*L4 -> 0.48979592 | O4: =M4/$E4 -> 0.0081632653 | P4: =N4/$E4 -> 0.012244898 | Q4: =O4*$C4*$D4 -> 22285.714 | R4: =P4*$C4*$D4 -> 33428.571
B5: Customer Care | C5: =_xlfn.XLOOKUP($B5,Inputs!$B$5:$B$9,Inputs!$C$5:$C$9) -> 51 | D5: =_xlfn.XLOOKUP($B5,Inputs!$B$5:$B$9,Inputs!I$5:I$9) -> 42352.941 | E5: =_xlfn.XLOOKUP($B5,Inputs!$B$5:$B$9,Inputs!H$5:H$9) -> 40 | F5: Issue resolution | G5: Automation | H5: Implement a Contact Center Co-Pilot that provides real-time, contextual guidance to agents for faster and more accurate issue resolution | I5: {=_xlfn.IFNA(_xlfn.XLOOKUP(B5&F5,'Activity by Category'!$B$4:$B$99&'Activity by Category'!$C$4:$C$99,'Activity by Category'!$E$4:$E$99)/100,1)} -> 0.85773563 | J5: =I5*_xlfn.XLOOKUP($B5,Inputs!$B$5:$B$9,Inputs!$H$5:$H$9) -> 34.309425 | K5: 0.2 | L5: 0.25 | M5: =$J5*K5 -> 6.861885 | N5: =$J5*L5 -> 8.5773563 | O5: =M5/$E5 -> 0.17154713 | P5: =N5/$E5 -> 0.21443391 | Q5: =O5*$C5*$D5 -> 370541.79 | R5: =P5*$C5*$D5 -> 463177.24
B6: R+R Pod | C6: =_xlfn.XLOOKUP($B6,Inputs!$B$5:$B$9,Inputs!$C$5:$C$9) -> 48 | D6: =_xlfn.XLOOKUP($B6,Inputs!$B$5:$B$9,Inputs!I$5:I$9) -> 56875 | E6: =_xlfn.XLOOKUP($B6,Inputs!$B$5:$B$9,Inputs!H$5:H$9) -> 40 | F6: Case management and processing | G6: Process | H6: Implement standardized intake checklist for new cases | I6: {=_xlfn.IFNA(_xlfn.XLOOKUP(B6&F6,'Activity by Category'!$B$4:$B$99&'Activity by Category'!$C$4:$C$99,'Activity by Category'!$E$4:$E$99)/100,1)} -> 0.66326531 | J6: =I6*_xlfn.XLOOKUP($B6,Inputs!$B$5:$B$9,Inputs!$H$5:$H$9) -> 26.530612 | K6: 0.04 | L6: 0.06 | M6: =$J6*K6 -> 1.0612245 | N6: =$J6*L6 -> 1.5918367 | O6: =M6/$E6 -> 0.026530612 | P6: =N6/$E6 -> 0.039795918 | Q6: =O6*$C6*$D6 -> 72428.571 | R6: =P6*$C6*$D6 -> 108642.86
B7: MTS Pod | C7: =_xlfn.XLOOKUP($B7,Inputs!$B$5:$B$9,Inputs!$C$5:$C$9) -> 73 | D7: =_xlfn.XLOOKUP($B7,Inputs!$B$5:$B$9,Inputs!I$5:I$9) -> 53424.658 | E7: =_xlfn.XLOOKUP($B7,Inputs!$B$5:$B$9,Inputs!H$5:H$9) -> 40 | F7: Shop creation | G7: Process | H7: Streamline QC and standardize review process to minimize rework | I7: {=_xlfn.IFNA(_xlfn.XLOOKUP(B7&F7,'Activity by Category'!$B$4:$B$99&'Activity by Category'!$C$4:$C$99,'Activity by Category'!$E$4:$E$99)/100,1)} -> 0.69306931 | J7: =I7*_xlfn.XLOOKUP($B7,Inputs!$B$5:$B$9,Inputs!$H$5:$H$9) -> 27.722772 | K7: 0.02 | L7: 0.03 | M7: =$J7*K7 -> 0.55445545 | N7: =$J7*L7 -> 0.83168317 | O7: =M7/$E7 -> 0.013861386 | P7: =N7/$E7 -> 0.020792079 | Q7: =O7*$C7*$D7 -> 54059.406 | R7: =P7*$C7*$D7 -> 81089.109
B8: R+R Pod | C8: =_xlfn.XLOOKUP($B8,Inputs!$B$5:$B$9,Inputs!$C$5:$C$9) -> 48 | D8: =_xlfn.XLOOKUP($B8,Inputs!$B$5:$B$9,Inputs!I$5:I$9) -> 56875 | E8: =_xlfn.XLOOKUP($B8,Inputs!$B$5:$B$9,Inputs!H$5:H$9) -> 40 | F8: Case management and processing | G8: Automation | H8: Provide self-serve channel for customers to initiate R+R | I8: {=_xlfn.IFNA(_xlfn.XLOOKUP(B8&F8,'Activity by Category'!$B$4:$B$99&'Activity by Category'!$C$4:$C$99,'Activity by Category'!$E$4:$E$99)/100,1)} -> 0.66326531 | J8: =I8*_xlfn.XLOOKUP($B8,Inputs!$B$5:$B$9,Inputs!$H$5:$H$9) -> 26.530612 | K8: 0.2 | L8: 0.3 | M8: =$J8*K8 -> 5.3061224 | N8: =$J8*L8 -> 7.9591837 | O8: =M8/$E8 -> 0.13265306 | P8: =N8/$E8 -> 0.19897959 | Q8: =O8*$C8*$D8 -> 362142.86 | R8: =P8*$C8*$D8 -> 543214.29
B9: TM | C9: =_xlfn.XLOOKUP($B9,Inputs!$B$5:$B$9,Inputs!$C$5:$C$9) -> 139 | D9: =_xlfn.XLOOKUP($B9,Inputs!$B$5:$B$9,Inputs!I$5:I$9) -> 60000 | E9: =_xlfn.XLOOKUP($B9,Inputs!$B$5:$B$9,Inputs!H$5:H$9) -> 40 | F9: Sales support activities | G9: Automation | H9: Deploy an AI Co-Pilot that instantly provides the right SKU and product details to speed up quoting and order creation | I9: {=_xlfn.IFNA(_xlfn.XLOOKUP(B9&F9,'Activity by Category'!$B$4:$B$99&'Activity by Category'!$C$4:$C$99,'Activity by Category'!$E$4:$E$99)/100,1)} -> 0.90697674 | J9: =I9*_xlfn.XLOOKUP($B9,Inputs!$B$5:$B$9,Inputs!$H$5:$H$9) -> 36.27907 | K9: 0.1 | L9: 0.15 | M9: =$J9*K9 -> 3.627907 | N9: =$J9*L9 -> 5.4418605 | O9: =M9/$E9 -> 0.090697674 | P9: =N9/$E9 -> 0.13604651 | Q9: =O9*$C9*$D9 -> 756418.6 | R9: =P9*$C9*$D9 -> 1134627.9
B10: MTS Pod | C10: =_xlfn.XLOOKUP($B10,Inputs!$B$5:$B$9,Inputs!$C$5:$C$9) -> 73 | D10: =_xlfn.XLOOKUP($B10,Inputs!$B$5:$B$9,Inputs!I$5:I$9) -> 53424.658 | E10: =_xlfn.XLOOKUP($B10,Inputs!$B$5:$B$9,Inputs!H$5:H$9) -> 40 | F10: Shop creation support activities | G10: Process | H10: Streamline MTS change requests processes | I10: {=_xlfn.IFNA(_xlfn.XLOOKUP(B10&F10,'Activity by Category'!$B$4:$B$99&'Activity by Category'!$C$4:$C$99,'Activity by Category'!$E$4:$E$99)/100,1)} -> 0.15841584 | J10: =I10*_xlfn.XLOOKUP($B10,Inputs!$B$5:$B$9,Inputs!$H$5:$H$9) -> 6.3366337 | K10: 0.1 | L10: 0.2 | M10: =$J10*K10 -> 0.63366337 | N10: =$J10*L10 -> 1.2673267 | O10: =M10/$E10 -> 0.015841584 | P10: =N10/$E10 -> 0.031683168 | Q10: =O10*$C10*$D10 -> 61782.178 | R10: =P10*$C10*$D10 -> 123564.36
B11: TM | C11: =_xlfn.XLOOKUP($B11,Inputs!$B$5:$B$9,Inputs!$C$5:$C$9) -> 139 | D11: =_xlfn.XLOOKUP($B11,Inputs!$B$5:$B$9,Inputs!I$5:I$9) -> 60000 | E11: =_xlfn.XLOOKUP($B11,Inputs!$B$5:$B$9,Inputs!H$5:H$9) -> 40 | F11: Sales support activities | G11: Automation | H11: Streamline cart and order creation with auto-fill for previous customer orders and costs | I11: {=_xlfn.IFNA(_xlfn.XLOOKUP(B11&F11,'Activity by Category'!$B$4:$B$99&'Activity by Category'!$C$4:$C$99,'Activity by Category'!$E$4:$E$99)/100,1)} -> 0.90697674 | J11: =I11*_xlfn.XLOOKUP($B11,Inputs!$B$5:$B$9,Inputs!$H$5:$H$9) -> 36.27907 | K11: 0.1 | L11: 0.15 | M11: =$J11*K11 -> 3.627907 | N11: =$J11*L11 -> 5.4418605 | O11: =M11/$E11 -> 0.090697674 | P11: =N11/$E11 -> 0.13604651 | Q11: =O11*$C11*$D11 -> 756418.6 | R11: =P11*$C11*$D11 -> 1134627.9
B12: SSR | C12: =_xlfn.XLOOKUP($B12,Inputs!$B$5:$B$9,Inputs!$C$5:$C$9) -> 188 | D12: =_xlfn.XLOOKUP($B12,Inputs!$B$5:$B$9,Inputs!I$5:I$9) -> 60000 | E12: =_xlfn.XLOOKUP($B12,Inputs!$B$5:$B$9,Inputs!H$5:H$9) -> 40 | F12: Order management | G12: Automation | H12: Use system integrations and dashboards to automate proactive order tracking and alerts - in progress | I12: {=_xlfn.IFNA(_xlfn.XLOOKUP(B12&F12,'Activity by Category'!$B$4:$B$99&'Activity by Category'!$C$4:$C$99,'Activity by Category'!$E$4:$E$99)/100,1)} -> 0.70454545 | J12: =I12*_xlfn.XLOOKUP($B12,Inputs!$B$5:$B$9,Inputs!$H$5:$H$9) -> 28.181818 | K12: 0.1 | L12: 0.15 | M12: =$J12*K12 -> 2.8181818 | N12: =$J12*L12 -> 4.2272727 | O12: =M12/$E12 -> 0.070454545 | P12: =N12/$E12 -> 0.10568182 | Q12: =O12*$C12*$D12 -> 794727.27 | R12: =P12*$C12*$D12 -> 1192090.9
B13: TM | C13: =_xlfn.XLOOKUP($B13,Inputs!$B$5:$B$9,Inputs!$C$5:$C$9) -> 139 | D13: =_xlfn.XLOOKUP($B13,Inputs!$B$5:$B$9,Inputs!I$5:I$9) -> 60000 | E13: =_xlfn.XLOOKUP($B13,Inputs!$B$5:$B$9,Inputs!H$5:H$9) -> 40 | F13: Sales support activities | G13: Process | H13: Clarify boundaries between TMs and SSRs for quoting vs. order setup | I13: {=_xlfn.IFNA(_xlfn.XLOOKUP(B13&F13,'Activity by Category'!$B$4:$B$99&'Activity by Category'!$C$4:$C$99,'Activity by Category'!$E$4:$E$99)/100,1)} -> 0.90697674 | J13: =I13*_xlfn.XLOOKUP($B13,Inputs!$B$5:$B$9,Inputs!$H$5:$H$9) -> 36.27907 | K13: 0.02 | L13: 0.03 | M13: =$J13*K13 -> 0.7255814 | N13: =$J13*L13 -> 1.0883721 | O13: =M13/$E13 -> 0.018139535 | P13: =N13/$E13 -> 0.027209302 | Q13: =O13*$C13*$D13 -> 151283.72 | R13: =P13*$C13*$D13 -> 226925.58
B14: SSR | C14: =_xlfn.XLOOKUP($B14,Inputs!$B$5:$B$9,Inputs!$C$5:$C$9) -> 188 | D14: =_xlfn.XLOOKUP($B14,Inputs!$B$5:$B$9,Inputs!I$5:I$9) -> 60000 | E14: =_xlfn.XLOOKUP($B14,Inputs!$B$5:$B$9,Inputs!H$5:H$9) -> 40 | F14: Order management | G14: Automation | H14: Auto-populate purchase order details using historical vendor data and enabling one-click PO duplication | I14: {=_xlfn.IFNA(_xlfn.XLOOKUP(B14&F14,'Activity by Category'!$B$4:$B$99&'Activity by Category'!$C$4:$C$99,'Activity by Category'!$E$4:$E$99)/100,1)} -> 0.70454545 | J14: =I14*_xlfn.XLOOKUP($B14,Inputs!$B$5:$B$9,Inputs!$H$5:$H$9) -> 28.181818 | K14: 0.1 | L14: 0.15 | M14: =$J14*K14 -> 2.8181818 | N14: =$J14*L14 -> 4.2272727 | O14: =M14/$E14 -> 0.070454545 | P14: =N14/$E14 -> 0.10568182 | Q14: =O14*$C14*$D14 -> 794727.27 | R14: =P14*$C14*$D14 -> 1192090.9
B15: R+R Pod | C15: =_xlfn.XLOOKUP($B15,Inputs!$B$5:$B$9,Inputs!$C$5:$C$9) -> 48 | D15: =_xlfn.XLOOKUP($B15,Inputs!$B$5:$B$9,Inputs!I$5:I$9) -> 56875 | E15: =_xlfn.XLOOKUP($B15,Inputs!$B$5:$B$9,Inputs!H$5:H$9) -> 40 | F15: Case management and processing | G15: Automation | H15: Auto-generate replacement orders (ZREP/RE), shipping labels, and freight pickup scheduling from case data | I15: {=_xlfn.IFNA(_xlfn.XLOOKUP(B15&F15,'Activity by Category'!$B$4:$B$99&'Activity by Category'!$C$4:$C$99,'Activity by Category'!$E$4:$E$99)/100,1)} -> 0.66326531 | J15: =I15*_xlfn.XLOOKUP($B15,Inputs!$B$5:$B$9,Inputs!$H$5:$H$9) -> 26.530612 | K15: 0.1 | L15: 0.15 | M15: =$J15*K15 -> 2.6530612 | N15: =$J15*L15 -> 3.9795918 | O15: =M15/$E15 -> 0.066326531 | P15: =N15/$E15 -> 0.099489796 | Q15: =O15*$C15*$D15 -> 181071.43 | R15: =P15*$C15*$D15 -> 271607.14
... B36: Customer Care | C36: =_xlfn.XLOOKUP($B36,Inputs!$B$5:$B$9,Inputs!$C$5:$C$9) -> 51 | D36: =_xlfn.XLOOKUP($B36,Inputs!$B$5:$B$9,Inputs!I$5:I$9) -> 42352.941 | E36: =_xlfn.XLOOKUP($B36,Inputs!$B$5:$B$9,Inputs!H$5:H$9) -> 40 | F36: Issue resolution | G36: Process | H36: Clarify ownership boundaries between Customer Care, SSRs, and R&R for order tracking and problem resolution | I36: {=_xlfn.IFNA(_xlfn.XLOOKUP(B36&F36,'Activity by Category'!$B$4:$B$99&'Activity by Category'!$C$4:$C$99,'Activity by Category'!$E$4:$E$99)/100,1)} -> 0.85773563 | J36: =I36*_xlfn.XLOOKUP($B36,Inputs!$B$5:$B$9,Inputs!$H$5:$H$9) -> 34.309425 | K36: 0.03 | L36: 0.05 | M36: =$J36*K36 -> 1.0292828 | N36: =$J36*L36 -> 1.7154713 | O36: =M36/$E36 -> 0.025732069 | P36: =N36/$E36 -> 0.042886781 | Q36: =O36*$C36*$D36 -> 55581.269 | R36: =P36*$C36*$D36 -> 92635.448

Sheet Temp (save)
B3: Order | C3: Role | D3: FTEs for ROLE | E3: Cost per year for ROLE | F3: Total hours per week for ROLE | G3: New archetype | H3: Category of opportunity | I3: Opportunity description | J3: Feasibility | K3: Feasibility label | L3: Description | M3: Current time spent on activity category (%) | N3: Current time spent on activity archetype (hrs per week) | O3: Efficiency gained on activity archetype % (low-end) | P3: Efficiency gained on activity archetype % (high-end) | Q3: Hours saved (low-end) | R3: Hours saved (high-end) | S3: Efficiency gained % on total workweek (low-end) | T3: Efficiency gained % on total workweek (high-end) | U3: $ impact (low-end) | V3: $ impact (high-end) | W3: Label
B4: 1 | C4: SSR | D4: =_xlfn.XLOOKUP($C4,Inputs!$B$5:$B$9,Inputs!C$5:C$9) -> 188 | E4: =_xlfn.XLOOKUP($C4,Inputs!$B$5:$B$9,Inputs!E$5:E$9) -> 60000 | F4: =_xlfn.XLOOKUP($C4,Inputs!$B$5:$B$9,Inputs!H$5:H$9) -> 40 | G4: Order management | H4: Automation | I4: Use system integrations and dashboards to automate proactive order tracking and alerts - in progress | J4: 2 – Medium | K4: 2 | L4: Already in progress; incremental development | M4: {=_xlfn.IFNA(_xlfn.XLOOKUP(C4&G4,'Activity by Category'!$B$4:$B$99&'Activity by Category'!$C$4:$C$99,'Activity by Category'!$E$4:$E$99)/100,1)} -> 0.70454545 | N4: =M4*_xlfn.XLOOKUP($C4,Inputs!$B$5:$B$9,Inputs!$H$5:$H$9) -> 28.181818 | O4: 0.1 | P4: 0.15 | Q4: =$N4*O4 -> 2.8181818 | R4: =$N4*P4 -> 4.2272727 | S4: =Q4/$F4 -> 0.070454545 | T4: =R4/$F4 -> 0.10568182 | U4: =S4*$D4*$E4 -> 794727.27 | V4: =T4*$D4*$E4 -> 1192090.9 | W4: 1
B5: 1 | C5: SSR | D5: =_xlfn.XLOOKUP($C5,Inputs!$B$5:$B$9,Inputs!C$5:C$9) -> 188 | E5: =_xlfn.XLOOKUP($C5,Inputs!$B$5:$B$9,Inputs!E$5:E$9) -> 60000 | F5: =_xlfn.XLOOKUP($C5,Inputs!$B$5:$B$9,Inputs!H$5:H$9) -> 40 | G5: Order management | H5: Automation | I5: Auto-populate purchase order details using historical vendor data and enabling one-click PO duplication | J5: 2 – Medium | K5: 2 | L5: Engage workflow logic update; moderate effort | M5: {=_xlfn.IFNA(_xlfn.XLOOKUP(C5&G5,'Activity by Category'!$B$4:$B$99&'Activity by Category'!$C$4:$C$99,'Activity by Category'!$E$4:$E$99)/100,1)} -> 0.70454545 | N5: =M5*_xlfn.XLOOKUP($C5,Inputs!$B$5:$B$9,Inputs!$H$5:$H$9) -> 28.181818 | O5: 0.1 | P5: 0.15 | Q5: =$N5*O5 -> 2.8181818 | R5: =$N5*P5 -> 4.2272727 | S5: =Q5/$F5 -> 0.070454545 | T5: =R5/$F5 -> 0.10568182 | U5: =S5*$D5*$E5 -> 794727.27 | V5: =T5*$D5*$E5 -> 1192090.9 | W5: 2
B6: 1 | C6: SSR | D6: =_xlfn.XLOOKUP($C6,Inputs!$B$5:$B$9,Inputs!C$5:C$9) -> 188 | E6: =_xlfn.XLOOKUP($C6,Inputs!$B$5:$B$9,Inputs!E$5:E$9) -> 60000 | F6: =_xlfn.XLOOKUP($C6,Inputs!$B$5:$B$9,Inputs!H$5:H$9) -> 40 | G6: Order management | H6: Automation | I6: Automatically detect and remove back-ordered or out-of-stock SKUs during order creation or extension | J6: 2 – Medium | K6: 2 | L6: System configuration and data rules; achievable but tech-involved | M6: {=_xlfn.IFNA(_xlfn.XLOOKUP(C6&G6,'Activity by Category'!$B$4:$B$99&'Activity by Category'!$C$4:$C$99,'Activity by Category'!$E$4:$E$99)/100,1)} -> 0.70454545 | N6: =M6*_xlfn.XLOOKUP($C6,Inputs!$B$5:$B$9,Inputs!$H$5:$H$9) -> 28.181818 | O6: 0.05 | P6: 0.1 | Q6: =$N6*O6 -> 1.4090909 | R6: =$N6*P6 -> 2.8181818 | S6: =Q6/$F6 -> 0.035227273 | T6: =R6/$F6 -> 0.070454545 | U6: =S6*$D6*$E6 -> 397363.64 | V6: =T6*$D6*$E6 -> 794727.27 | W6: 3
B7: 1 | C7: SSR | D7: =_xlfn.XLOOKUP($C7,Inputs!$B$5:$B$9,Inputs!C$5:C$9) -> 188 | E7: =_xlfn.XLOOKUP($C7,Inputs!$B$5:$B$9,Inputs!E$5:E$9) -> 60000 | F7: =_xlfn.XLOOKUP($C7,Inputs!$B$5:$B$9,Inputs!H$5:H$9) -> 40 | G7: Order management | H7: Process | I7: Create standardized communication templates for recurring inquiries (e.g., SAP order corrections, order status updates) | J7: 3 – High | K7: 3 | L7: Low tech dependency; clear process gain | M7: {=_xlfn.IFNA(_xlfn.XLOOKUP(C7&G7,'Activity by Category'!$B$4:$B$99&'Activity by Category'!$C$4:$C$99,'Activity by Category'!$E$4:$E$99)/100,1)} -> 0.70454545 | N7: =M7*_xlfn.XLOOKUP($C7,Inputs!$B$5:$B$9,Inputs!$H$5:$H$9) -> 28.181818 | O7: 0.02 | P7: 0.05 | Q7: =$N7*O7 -> 0.56363636 | R7: =$N7*P7 -> 1.4090909 | S7: =Q7/$F7 -> 0.014090909 | T7: =R7/$F7 -> 0.035227273 | U7: =S7*$D7*$E7 -> 158945.45 | V7: =T7*$D7*$E7 -> 397363.64 | W7: 4
B8: 1 | C8: SSR | D8: =_xlfn.XLOOKUP($C8,Inputs!$B$5:$B$9,Inputs!C$5:C$9) -> 188 | E8: =_xlfn.XLOOKUP($C8,Inputs!$B$5:$B$9,Inputs!E$5:E$9) -> 60000 | F8: =_xlfn.XLOOKUP($C8,Inputs!$B$5:$B$9,Inputs!H$5:H$9) -> 40 | G8: Issue resolution | H8: Automation | I8: Implement smart routing and exception handling to focus reps on complex cases | J8: 2 – Medium | K8: 2 | L8: Moderate Engage workflow logic required | M8: {=_xlfn.IFNA(_xlfn.XLOOKUP(C8&G8,'Activity by Category'!$B$4:$B$99&'Activity by Category'!$C$4:$C$99,'Activity by Category'!$E$4:$E$99)/100,1)} -> 0.17045455 | N8: =M8*_xlfn.XLOOKUP($C8,Inputs!$B$5:$B$9,Inputs!$H$5:$H$9) -> 6.8181818 | O8: 0.15 | P8: 0.2 | Q8: =$N8*O8 -> 1.0227273 | R8: =$N8*P8 -> 1.3636364 | S8: =Q8/$F8 -> 0.025568182 | T8: =R8/$F8 -> 0.034090909 | U8: =S8*$D8*$E8 -> 288409.09 | V8: =T8*$D8*$E8 -> 384545.45 | W8: 5
B9: 1 | C9: SSR | D9: =_xlfn.XLOOKUP($C9,Inputs!$B$5:$B$9,Inputs!C$5:C$9) -> 188 | E9: =_xlfn.XLOOKUP($C9,Inputs!$B$5:$B$9,Inputs!E$5:E$9) -> 60000 | F9: =_xlfn.XLOOKUP($C9,Inputs!$B$5:$B$9,Inputs!H$5:H$9) -> 40 | G9: Issue resolution | H9: Process | I9: Redesign post-order processes to reduce redundant communication loops and follow-ups | J9: 2 – Medium | K9: 2 | L9: Governance and coordination changes; achievable with clear SOPs | M9: {=_xlfn.IFNA(_xlfn.XLOOKUP(C9&G9,'Activity by Category'!$B$4:$B$99&'Activity by Category'!$C$4:$C$99,'Activity by Category'!$E$4:$E$99)/100,1)} -> 0.17045455 | N9: =M9*_xlfn.XLOOKUP($C9,Inputs!$B$5:$B$9,Inputs!$H$5:$H$9) -> 6.8181818 | O9: 0.05 | P9: 0.1 | Q9: =$N9*O9 -> 0.34090909 | R9: =$N9*P9 -> 0.68181818 | S9: =Q9/$F9 -> 0.0085227273 | T9: =R9/$F9 -> 0.017045455 | U9: =S9*$D9*$E9 -> 96136.364 | V9: =T9*$D9*$E9 -> 192272.73 | W9: 6
B10: 2 | C10: TM | D10: =_xlfn.XLOOKUP($C10,Inputs!$B$5:$B$9,Inputs!C$5:C$9) -> 139 | E10: =_xlfn.XLOOKUP($C10,Inputs!$B$5:$B$9,Inputs!E$5:E$9) -> 60000 | F10: =_xlfn.XLOOKUP($C10,Inputs!$B$5:$B$9,Inputs!H$5:H$9) -> 40 | G10: Sales support activities | H10: Automation | I10: Streamline cart and order creation with auto-fill for previous customer orders and costs | J10: 2 – Medium | K10: 2 | L10: System logic enhancement; dependent on CRM customization | M10: {=_xlfn.IFNA(_xlfn.XLOOKUP(C10&G10,'Activity by Category'!$B$4:$B$99&'Activity by Category'!$C$4:$C$99,'Activity by Category'!$E$4:$E$99)/100,1)} -> 0.90697674 | N10: =M10*_xlfn.XLOOKUP($C10,Inputs!$B$5:$B$9,Inputs!$H$5:$H$9) -> 36.27907 | O10: 0.1 | P10: 0.15 | Q10: =$N10*O10 -> 3.627907 | R10: =$N10*P10 -> 5.4418605 | S10: =Q10/$F10 -> 0.090697674 | T10: =R10/$F10 -> 0.13604651 | U10: =S10*$D10*$E10 -> 756418.6 | V10: =T10*$D10*$E10 -> 1134627.9 | W10: 7
B11: 2 | C11: TM | D11: =_xlfn.XLOOKUP($C11,Inputs!$B$5:$B$9,Inputs!C$5:C$9) -> 139 | E11: =_xlfn.XLOOKUP($C11,Inputs!$B$5:$B$9,Inputs!E$5:E$9) -> 60000 | F11: =_xlfn.XLOOKUP($C11,Inputs!$B$5:$B$9,Inputs!H$5:H$9) -> 40 | G11: Sales support activities | H11: Process | I11: Align data fields across CRM and Engage to eliminate re-entry | J11: 2 – Medium | K11: 2 | L11: Integration light lift but requires IT coordination | M11: {=_xlfn.IFNA(_xlfn.XLOOKUP(C11&G11,'Activity by Category'!$B$4:$B$99&'Activity by Category'!$C$4:$C$99,'Activity by Category'!$E$4:$E$99)/100,1)} -> 0.90697674 | N11: =M11*_xlfn.XLOOKUP($C11,Inputs!$B$5:$B$9,Inputs!$H$5:$H$9) -> 36.27907 | O11: 0.05 | P11: 0.1 | Q11: =$N11*O11 -> 1.8139535 | R11: =$N11*P11 -> 3.627907 | S11: =Q11/$F11 -> 0.045348837 | T11: =R11/$F11 -> 0.090697674 | U11: =S11*$D11*$E11 -> 378209.3 | V11: =T11*$D11*$E11 -> 756418.6 | W11: 8
B12: 2 | C12: TM | D12: =_xlfn.XLOOKUP($C12,Inputs!$B$5:$B$9,Inputs!C$5:C$9) -> 139 | E12: =_xlfn.XLOOKUP($C12,Inputs!$B$5:$B$9,Inputs!E$5:E$9) -> 60000 | F12: =_xlfn.XLOOKUP($C12,Inputs!$B$5:$B$9,Inputs!H$5:H$9) -> 40 | G12: Sales support activities | H12: Automation | I12: Auto-suggest products, bundles, or pricing tiers based on customer history, region, and performance data | J12: 1 – Low | K12: 1 | L12: Requires AI model training and CRM integration; high tech dependency | M12: {=_xlfn.IFNA(_xlfn.XLOOKUP(C12&G12,'Activity by Category'!$B$4:$B$99&'Activity by Category'!$C$4:$C$99,'Activity by Category'!$E$4:$E$99)/100,1)} -> 0.90697674 | N12: =M12*_xlfn.XLOOKUP($C12,Inputs!$B$5:$B$9,Inputs!$H$5:$H$9) -> 36.27907 | O12: 0.05 | P12: 0.1 | Q12: =$N12*O12 -> 1.8139535 | R12: =$N12*P12 -> 3.627907 | S12: =Q12/$F12 -> 0.045348837 | T12: =R12/$F12 -> 0.090697674 | U12: =S12*$D12*$E12 -> 378209.3 | V12: =T12*$D12*$E12 -> 756418.6 | W12: 9
B13: 2 | C13: TM | D13: =_xlfn.XLOOKUP($C13,Inputs!$B$5:$B$9,Inputs!C$5:C$9) -> 139 | E13: =_xlfn.XLOOKUP($C13,Inputs!$B$5:$B$9,Inputs!E$5:E$9) -> 60000 | F13: =_xlfn.XLOOKUP($C13,Inputs!$B$5:$B$9,Inputs!H$5:H$9) -> 40 | G13: Sales support activities | H13: Process | I13: Standardize quote-to-order workflow and templates to minimize manual input | J13: 3 – High | K13: 3 | L13: Simple process documentation; templates already partially exist | M13: {=_xlfn.IFNA(_xlfn.XLOOKUP(C13&G13,'Activity by Category'!$B$4:$B$99&'Activity by Category'!$C$4:$C$99,'Activity by Category'!$E$4:$E$99)/100,1)} -> 0.90697674 | N13: =M13*_xlfn.XLOOKUP($C13,Inputs!$B$5:$B$9,Inputs!$H$5:$H$9) -> 36.27907 | O13: 0.03 | P13: 0.05 | Q13: =$N13*O13 -> 1.0883721 | R13: =$N13*P13 -> 1.8139535 | S13: =Q13/$F13 -> 0.027209302 | T13: =R13/$F13 -> 0.045348837 | U13: =S13*$D13*$E13 -> 226925.58 | V13: =T13*$D13*$E13 -> 378209.3 | W13: 10
B14: 2 | C14: TM | D14: =_xlfn.XLOOKUP($C14,Inputs!$B$5:$B$9,Inputs!C$5:C$9) -> 139 | E14: =_xlfn.XLOOKUP($C14,Inputs!$B$5:$B$9,Inputs!E$5:E$9) -> 60000 | F14: =_xlfn.XLOOKUP($C14,Inputs!$B$5:$B$9,Inputs!H$5:H$9) -> 40 | G14: Sales support activities | H14: Process | I14: Clarify boundaries between TMs and SSRs for quoting vs. order setup | J14: 3 – High | K14: 3 | L14: Organizational clarification; no tech dependency | M14: {=_xlfn.IFNA(_xlfn.XLOOKUP(C14&G14,'Activity by Category'!$B$4:$B$99&'Activity by Category'!$C$4:$C$99,'Activity by Category'!$E$4:$E$99)/100,1)} -> 0.90697674 | N14: =M14*_xlfn.XLOOKUP($C14,Inputs!$B$5:$B$9,Inputs!$H$5:$H$9) -> 36.27907 | O14: 0.02 | P14: 0.03 | Q14: =$N14*O14 -> 0.7255814 | R14: =$N14*P14 -> 1.0883721 | S14: =Q14/$F14 -> 0.018139535 | T14: =R14/$F14 -> 0.027209302 | U14: =S14*$D14*$E14 -> 151283.72 | V14: =T14*$D14*$E14 -> 226925.58 | W14: 11
B15: 3 | C15: MTS Pod | D15: =_xlfn.XLOOKUP($C15,Inputs!$B$5:$B$9,Inputs!C$5:C$9) -> 73 | E15: =_xlfn.XLOOKUP($C15,Inputs!$B$5:$B$9,Inputs!E$5:E$9) -> 60000 | F15: =_xlfn.XLOOKUP($C15,Inputs!$B$5:$B$9,Inputs!H$5:H$9) -> 40 | G15: Shop creation | H15: Automation | I15: Develop ready-to-use shop templates by sport or season with pre-approved products, pricing, and images | J15: 3 – High | K15: 3 | L15: Low technical lift; preconfiguration and governance | M15: {=_xlfn.IFNA(_xlfn.XLOOKUP(C15&G15,'Activity by Category'!$B$4:$B$99&'Activity by Category'!$C$4:$C$99,'Activity by Category'!$E$4:$E$99)/100,1)} -> 0.69306931 | N15: =M15*_xlfn.XLOOKUP($C15,Inputs!$B$5:$B$9,Inputs!$H$5:$H$9) -> 27.722772 | O15: 0.3 | P15: 0.4 | Q15: =$N15*O15 -> 8.3168317 | R15: =$N15*P15 -> 11.089109 | S15: =Q15/$F15 -> 0.20792079 | T15: =R15/$F15 -> 0.27722772 | U15: =S15*$D15*$E15 -> 910693.07 | V15: =T15*$D15*$E15 -> 1214257.4 | W15: 12
... B32: 5 | C32: R+R Pod | D32: =_xlfn.XLOOKUP($C32,Inputs!$B$5:$B$9,Inputs!C$5:C$9) -> 48 | E32: =_xlfn.XLOOKUP($C32,Inputs!$B$5:$B$9,Inputs!E$5:E$9) -> 60000 | F32: =_xlfn.XLOOKUP($C32,Inputs!$B$5:$B$9,Inputs!H$5:H$9) -> 40 | G32: Communication & coordination | H32: Process | I32: Standardize and schedule reminder templates for vendor follow-ups (e.g., pending return authorization, missing info) | J32: 3 – High | K32: 3 | L32: Simple process documentation and SOP rollout; minimal tech dependency | M32: {=_xlfn.IFNA(_xlfn.XLOOKUP(C32&G32,'Activity by Category'!$B$4:$B$99&'Activity by Category'!$C$4:$C$99,'Activity by Category'!$E$4:$E$99)/100,1)} -> 0.20408163 | N32: =M32*_xlfn.XLOOKUP($C32,Inputs!$B$5:$B$9,Inputs!$H$5:$H$9) -> 8.1632653 | O32: 0.04 | P32: 0.06 | Q32: =$N32*O32 -> 0.32653061 | R32: =$N32*P32 -> 0.48979592 | S32: =Q32/$F32 -> 0.0081632653 | T32: =R32/$F32 -> 0.012244898 | U32: =S32*$D32*$E32 -> 23510.204 | V32: =T32*$D32*$E32 -> 35265.306 | W32: 29

Sheet Activity by Category
E2: 100
B3: Role | C3: Activity | D3: Median % of Time | E3: Scaled Median % of Time
B4: Customer Care | C4: Other activities | D4: =SUMIFS('Activity Mapping'!F$3:F$73,'Activity Mapping'!$E$3:$E$73,$B4,'Activity Mapping'!$H$3:$H$73,$C4) -> 12 | E4: =D4/SUMIFS($D$4:$D$30,$B$4:$B$30,B4)*$E$2 -> 14.226437
B5: Customer Care | C5: Issue resolution | D5: =SUMIFS('Activity Mapping'!F$3:F$73,'Activity Mapping'!$E$3:$E$73,$B5,'Activity Mapping'!$H$3:$H$73,$C5) -> 72.35 | E5: =D5/SUMIFS($D$4:$D$30,$B$4:$B$30,B5)*$E$2 -> 85.773563
B6: SSR | C6: Issue resolution | D6: =SUMIFS('Activity Mapping'!F$3:F$73,'Activity Mapping'!$E$3:$E$73,$B6,'Activity Mapping'!$H$3:$H$73,$C6) -> 15 | E6: =D6/SUMIFS($D$4:$D$30,$B$4:$B$30,B6)*$E$2 -> 17.045455
B7: SSR | C7: Order management | D7: =SUMIFS('Activity Mapping'!F$3:F$73,'Activity Mapping'!$E$3:$E$73,$B7,'Activity Mapping'!$H$3:$H$73,$C7) -> 62 | E7: =D7/SUMIFS($D$4:$D$30,$B$4:$B$30,B7)*$E$2 -> 70.454545
B8: SSR | C8: Other activities | D8: =SUMIFS('Activity Mapping'!F$3:F$73,'Activity Mapping'!$E$3:$E$73,$B8,'Activity Mapping'!$H$3:$H$73,$C8) -> 11 | E8: =D8/SUMIFS($D$4:$D$30,$B$4:$B$30,B8)*$E$2 -> 12.5
B9: TM | C9: Other activities | D9: =SUMIFS('Activity Mapping'!F$3:F$73,'Activity Mapping'!$E$3:$E$73,$B9,'Activity Mapping'!$H$3:$H$73,$C9) -> 8 | E9: =D9/SUMIFS($D$4:$D$30,$B$4:$B$30,B9)*$E$2 -> 9.3023256
B10: TM | C10: Sales support activities | D10: =SUMIFS('Activity Mapping'!F$3:F$73,'Activity Mapping'!$E$3:$E$73,$B10,'Activity Mapping'!$H$3:$H$73,$C10) -> 78 | E10: =D10/SUMIFS($D$4:$D$30,$B$4:$B$30,B10)*$E$2 -> 90.697674
B11: R+R Pod | C11: Case management and processing | D11: =SUMIFS('Activity Mapping'!F$3:F$73,'Activity Mapping'!$E$3:$E$73,$B11,'Activity Mapping'!$H$3:$H$73,$C11) -> 65 | E11: =D11/SUMIFS($D$4:$D$30,$B$4:$B$30,B11)*$E$2 -> 66.326531
B12: R+R Pod | C12: Communication & coordination | D12: =SUMIFS('Activity Mapping'!F$3:F$73,'Activity Mapping'!$E$3:$E$73,$B12,'Activity Mapping'!$H$3:$H$73,$C12) -> 20 | E12: =D12/SUMIFS($D$4:$D$30,$B$4:$B$30,B12)*$E$2 -> 20.408163
B13: R+R Pod | C13: Other activities | D13: =SUMIFS('Activity Mapping'!F$3:F$73,'Activity Mapping'!$E$3:$E$73,$B13,'Activity Mapping'!$H$3:$H$73,$C13) -> 13 | E13: =D13/SUMIFS($D$4:$D$30,$B$4:$B$30,B13)*$E$2 -> 13.265306
B14: MTS Pod | C14: Other activities | D14: =SUMIFS('Activity Mapping'!F$3:F$73,'Activity Mapping'!$E$3:$E$73,$B14,'Activity Mapping'!$H$3:$H$73,$C14) -> 15 | E14: =D14/SUMIFS($D$4:$D$30,$B$4:$B$30,B14)*$E$2 -> 14.851485
B15: MTS Pod | C15: Shop creation | D15: =SUMIFS('Activity Mapping'!F$3:F$73,'Activity Mapping'!$E$3:$E$73,$B15,'Activity Mapping'!$H$3:$H$73,$C15) -> 70 | E15: =D15/SUMIFS($D$4:$D$30,$B$4:$B$30,B15)*$E$2 -> 69.306931
B16: MTS Pod | C16: Shop creation support activities | D16: =SUMIFS('Activity Mapping'!F$3:F$73,'Activity Mapping'!$E$3:$E$73,$B16,'Activity Mapping'!$H$3:$H$73,$C16) -> 16 | E16: =D16/SUMIFS($D$4:$D$30,$B$4:$B$30,B16)*$E$2 -> 15.841584

Sheet Temp
A3: order | B3: Role | C3: FTEs for ROLE | D3: Cost per year for ROLE | E3: Total hours per week for ROLE | F3: Archetype | G3: Category of opportunity | H3: Opportunity description | I3: Current time spent on activity category (%) | J3: Current time spent on activity archetype (hrs per week) | K3: Efficiency gained on activity archetype % (low-end) | L3: Efficiency gained on activity archetype % (high-end) | M3: Hours saved (low-end) | N3: Hours saved (high-end) | O3: Efficiency gained % on total workweek (low-end) | P3: Efficiency gained % on total workweek (high-end) | Q3: $ impact (low-end) | R3: $ impact (high-end) | S3: rank | T3: Label
A4: 1 | B4: SSR | C4: =_xlfn.XLOOKUP($B4,Inputs!$B$5:$B$9,Inputs!$D$5:$D$9) -> 188 | D4: =_xlfn.XLOOKUP($B4,Inputs!$B$5:$B$9,Inputs!E$5:E$9) -> 60000 | E4: =_xlfn.XLOOKUP($B4,Inputs!$B$5:$B$9,Inputs!H$5:H$9) -> 40 | F4: Order management | G4: Automation | H4: Use system integrations and dashboards to automate proactive order tracking and alerts - in progress | I4: {=_xlfn.IFNA(_xlfn.XLOOKUP(B4&F4,'Activity by Category'!$B$4:$B$99&'Activity by Category'!$C$4:$C$99,'Activity by Category'!$E$4:$E$99)/100,1)} -> 0.70454545 | J4: =I4*_xlfn.XLOOKUP($B4,Inputs!$B$5:$B$9,Inputs!$H$5:$H$9) -> 28.181818 | K4: 0.1 | L4: 0.15 | M4: =$J4*K4 -> 2.8181818 | N4: =$J4*L4 -> 4.2272727 | O4: =M4/$E4 -> 0.070454545 | P4: =N4/$E4 -> 0.10568182 | Q4: =O4*$C4*$D4 -> 794727.27 | R4: =P4*$C4*$D4 -> 1192090.9 | S4: 1 | T4: BB
A5: 1 | B5: SSR | C5: =_xlfn.XLOOKUP($B5,Inputs!$B$5:$B$9,Inputs!$D$5:$D$9) -> 188 | D5: =_xlfn.XLOOKUP($B5,Inputs!$B$5:$B$9,Inputs!E$5:E$9) -> 60000 | E5: =_xlfn.XLOOKUP($B5,Inputs!$B$5:$B$9,Inputs!H$5:H$9) -> 40 | F5: Order management | G5: Automation | H5: Auto-populate purchase order details using historical vendor data and enabling one-click PO duplication | I5: {=_xlfn.IFNA(_xlfn.XLOOKUP(B5&F5,'Activity by Category'!$B$4:$B$99&'Activity by Category'!$C$4:$C$99,'Activity by Category'!$E$4:$E$99)/100,1)} -> 0.70454545 | J5: =I5*_xlfn.XLOOKUP($B5,Inputs!$B$5:$B$9,Inputs!$H$5:$H$9) -> 28.181818 | K5: 0.1 | L5: 0.15 | M5: =$J5*K5 -> 2.8181818 | N5: =$J5*L5 -> 4.2272727 | O5: =M5/$E5 -> 0.070454545 | P5: =N5/$E5 -> 0.10568182 | Q5: =O5*$C5*$D5 -> 794727.27 | R5: =P5*$C5*$D5 -> 1192090.9 | S5: 2 | T5: bb
A6: 2 | B6: TM | C6: =_xlfn.XLOOKUP($B6,Inputs!$B$5:$B$9,Inputs!$D$5:$D$9) -> 139 | D6: =_xlfn.XLOOKUP($B6,Inputs!$B$5:$B$9,Inputs!E$5:E$9) -> 60000 | E6: =_xlfn.XLOOKUP($B6,Inputs!$B$5:$B$9,Inputs!H$5:H$9) -> 40 | F6: Sales support activities | G6: Automation | H6: Streamline cart and order creation with auto-fill for previous customer orders and costs | I6: {=_xlfn.IFNA(_xlfn.XLOOKUP(B6&F6,'Activity by Category'!$B$4:$B$99&'Activity by Category'!$C$4:$C$99,'Activity by Category'!$E$4:$E$99)/100,1)} -> 0.90697674 | J6: =I6*_xlfn.XLOOKUP($B6,Inputs!$B$5:$B$9,Inputs!$H$5:$H$9) -> 36.27907 | K6: 0.1 | L6: 0.15 | M6: =$J6*K6 -> 3.627907 | N6: =$J6*L6 -> 5.4418605 | O6: =M6/$E6 -> 0.090697674 | P6: =N6/$E6 -> 0.13604651 | Q6: =O6*$C6*$D6 -> 756418.6 | R6: =P6*$C6*$D6 -> 1134627.9 | S6: 10 | T6: BB
A7: 2 | B7: TM | C7: =_xlfn.XLOOKUP($B7,Inputs!$B$5:$B$9,Inputs!$D$5:$D$9) -> 139 | D7: =_xlfn.XLOOKUP($B7,Inputs!$B$5:$B$9,Inputs!E$5:E$9) -> 60000 | E7: =_xlfn.XLOOKUP($B7,Inputs!$B$5:$B$9,Inputs!H$5:H$9) -> 40 | F7: Sales support activities | G7: Automation | H7: Deploy an AI Co-Pilot that instantly provides the right SKU and product details to speed up quoting and order creation | I7: {=_xlfn.IFNA(_xlfn.XLOOKUP(B7&F7,'Activity by Category'!$B$4:$B$99&'Activity by Category'!$C$4:$C$99,'Activity by Category'!$E$4:$E$99)/100,1)} -> 0.90697674 | J7: =I7*_xlfn.XLOOKUP($B7,Inputs!$B$5:$B$9,Inputs!$H$5:$H$9) -> 36.27907 | K7: 0.1 | L7: 0.15 | M7: =$J7*K7 -> 3.627907 | N7: =$J7*L7 -> 5.4418605 | O7: =M7/$E7 -> 0.090697674 | P7: =N7/$E7 -> 0.13604651 | Q7: =O7*$C7*$D7 -> 756418.6 | R7: =P7*$C7*$D7 -> 1134627.9 | S7: 9 | T7: bb
A8: 3 | B8: MTS Pod | C8: =_xlfn.XLOOKUP($B8,Inputs!$B$5:$B$9,Inputs!$D$5:$D$9) -> 57 | D8: =_xlfn.XLOOKUP($B8,Inputs!$B$5:$B$9,Inputs!E$5:E$9) -> 60000 | E8: =_xlfn.XLOOKUP($B8,Inputs!$B$5:$B$9,Inputs!H$5:H$9) -> 40 | F8: Shop creation | G8: Process | H8: Develop ready-to-use shop build templates by sport or season with pre-approved products, pricing, and images | I8: {=_xlfn.IFNA(_xlfn.XLOOKUP(B8&F8,'Activity by Category'!$B$4:$B$99&'Activity by Category'!$C$4:$C$99,'Activity by Category'!$E$4:$E$99)/100,1)} -> 0.69306931 | J8: =I8*_xlfn.XLOOKUP($B8,Inputs!$B$5:$B$9,Inputs!$H$5:$H$9) -> 27.722772 | K8: 0.3 | L8: 0.4 | M8: =$J8*K8 -> 8.3168317 | N8: =$J8*L8 -> 11.089109 | O8: =M8/$E8 -> 0.20792079 | P8: =N8/$E8 -> 0.27722772 | Q8: =O8*$C8*$D8 -> 711089.11 | R8: =P8*$C8*$D8 -> 948118.81 | S8: 16 | T8: BB
A9: 2 | B9: TM | C9: =_xlfn.XLOOKUP($B9,Inputs!$B$5:$B$9,Inputs!$D$5:$D$9) -> 139 | D9: =_xlfn.XLOOKUP($B9,Inputs!$B$5:$B$9,Inputs!E$5:E$9) -> 60000 | E9: =_xlfn.XLOOKUP($B9,Inputs!$B$5:$B$9,Inputs!H$5:H$9) -> 40 | F9: Sales support activities | G9: Automation | H9: Implement a conversational Co-Pilot that generates complete carts from customer requirements, removing the need for manual SKU selection and speeding up quote creation | I9: {=_xlfn.IFNA(_xlfn.XLOOKUP(B9&F9,'Activity by Category'!$B$4:$B$99&'Activity by Category'!$C$4:$C$99,'Activity by Category'!$E$4:$E$99)/100,1)} -> 0.90697674 | J9: =I9*_xlfn.XLOOKUP($B9,Inputs!$B$5:$B$9,Inputs!$H$5:$H$9) -> 36.27907 | K9: 0.07 | L9: 0.12 | M9: =$J9*K9 -> 2.5395349 | N9: =$J9*L9 -> 4.3534884 | O9: =M9/$E9 -> 0.063488372 | P9: =N9/$E9 -> 0.10883721 | Q9: =O9*$C9*$D9 -> 529493.02 | R9: =P9*$C9*$D9 -> 907702.33 | S9: 11 | T9: bb
A10: 1 | B10: SSR | C10: =_xlfn.XLOOKUP($B10,Inputs!$B$5:$B$9,Inputs!$D$5:$D$9) -> 188 | D10: =_xlfn.XLOOKUP($B10,Inputs!$B$5:$B$9,Inputs!E$5:E$9) -> 60000 | E10: =_xlfn.XLOOKUP($B10,Inputs!$B$5:$B$9,Inputs!H$5:H$9) -> 40 | F10: Order management | G10: Automation | H10: Automatically detect and remove back-ordered or out-of-stock SKUs during order creation or extension | I10: {=_xlfn.IFNA(_xlfn.XLOOKUP(B10&F10,'Activity by Category'!$B$4:$B$99&'Activity by Category'!$C$4:$C$99,'Activity by Category'!$E$4:$E$99)/100,1)} -> 0.70454545 | J10: =I10*_xlfn.XLOOKUP($B10,Inputs!$B$5:$B$9,Inputs!$H$5:$H$9) -> 28.181818 | K10: 0.05 | L10: 0.1 | M10: =$J10*K10 -> 1.4090909 | N10: =$J10*L10 -> 2.8181818 | O10: =M10/$E10 -> 0.035227273 | P10: =N10/$E10 -> 0.070454545 | Q10: =O10*$C10*$D10 -> 397363.64 | R10: =P10*$C10*$D10 -> 794727.27 | S10: 3 | T10: bb
A11: 2 | B11: TM | C11: =_xlfn.XLOOKUP($B11,Inputs!$B$5:$B$9,Inputs!$D$5:$D$9) -> 139 | D11: =_xlfn.XLOOKUP($B11,Inputs!$B$5:$B$9,Inputs!E$5:E$9) -> 60000 | E11: =_xlfn.XLOOKUP($B11,Inputs!$B$5:$B$9,Inputs!H$5:H$9) -> 40 | F11: Sales support activities | G11: Process | H11: Align data fields across CRM and Engage to eliminate re-entry | I11: {=_xlfn.IFNA(_xlfn.XLOOKUP(B11&F11,'Activity by Category'!$B$4:$B$99&'Activity by Category'!$C$4:$C$99,'Activity by Category'!$E$4:$E$99)/100,1)} -> 0.90697674 | J11: =I11*_xlfn.XLOOKUP($B11,Inputs!$B$5:$B$9,Inputs!$H$5:$H$9) -> 36.27907 | K11: 0.05 | L11: 0.1 | M11: =$J11*K11 -> 1.8139535 | N11: =$J11*L11 -> 3.627907 | O11: =M11/$E11 -> 0.045348837 | P11: =N11/$E11 -> 0.090697674 | Q11: =O11*$C11*$D11 -> 378209.3 | R11: =P11*$C11*$D11 -> 756418.6 | S11: 12 | T11: bb
A12: 2 | B12: TM | C12: =_xlfn.XLOOKUP($B12,Inputs!$B$5:$B$9,Inputs!$D$5:$D$9) -> 139 | D12: =_xlfn.XLOOKUP($B12,Inputs!$B$5:$B$9,Inputs!E$5:E$9) -> 60000 | E12: =_xlfn.XLOOKUP($B12,Inputs!$B$5:$B$9,Inputs!H$5:H$9) -> 40 | F12: Sales support activities | G12: Automation | H12: Auto-suggest products, bundles, or pricing tiers based on customer history, region, and performance data | I12: {=_xlfn.IFNA(_xlfn.XLOOKUP(B12&F12,'Activity by Category'!$B$4:$B$99&'Activity by Category'!$C$4:$C$99,'Activity by Category'!$E$4:$E$99)/100,1)} -> 0.90697674 | J12: =I12*_xlfn.XLOOKUP($B12,Inputs!$B$5:$B$9,Inputs!$H$5:$H$9) -> 36.27907 | K12: 0.05 | L12: 0.1 | M12: =$J12*K12 -> 1.8139535 | N12: =$J12*L12 -> 3.627907 | O12: =M12/$E12 -> 0.045348837 | P12: =N12/$E12 -> 0.090697674 | Q12: =O12*$C12*$D12 -> 378209.3 | R12: =P12*$C12*$D12 -> 756418.6 | S12: 13 | T12: bb
A13: 4 | B13: Customer Care | C13: =_xlfn.XLOOKUP($B13,Inputs!$B$5:$B$9,Inputs!$D$5:$D$9) -> 21 | D13: =_xlfn.XLOOKUP($B13,Inputs!$B$5:$B$9,Inputs!E$5:E$9) -> 60000 | E13: =_xlfn.XLOOKUP($B13,Inputs!$B$5:$B$9,Inputs!H$5:H$9) -> 40 | F13: Issue resolution | G13: Automation | H13: Implement a Contact Center Co-Pilot that provides real-time, contextual guidance to agents for faster and more accurate issue resolution | I13: {=_xlfn.IFNA(_xlfn.XLOOKUP(B13&F13,'Activity by Category'!$B$4:$B$99&'Activity by Category'!$C$4:$C$99,'Activity by Category'!$E$4:$E$99)/100,1)} -> 0.85773563 | J13: =I13*_xlfn.XLOOKUP($B13,Inputs!$B$5:$B$9,Inputs!$H$5:$H$9) -> 34.309425 | K13: 0.25 | L13: 0.35 | M13: =$J13*K13 -> 8.5773563 | N13: =$J13*L13 -> 12.008299 | O13: =M13/$E13 -> 0.21443391 | P13: =N13/$E13 -> 0.30020747 | Q13: =O13*$C13*$D13 -> 270186.72 | R13: =P13*$C13*$D13 -> 378261.41 | S13: 22 | T13: bb
A14: 3 | B14: MTS Pod | C14: =_xlfn.XLOOKUP($B14,Inputs!$B$5:$B$9,Inputs!$D$5:$D$9) -> 57 | D14: =_xlfn.XLOOKUP($B14,Inputs!$B$5:$B$9,Inputs!E$5:E$9) -> 60000 | E14: =_xlfn.XLOOKUP($B14,Inputs!$B$5:$B$9,Inputs!H$5:H$9) -> 40 | F14: Shop creation | G14: Process | H14: Reduce or eliminate unprofitable demo shop creations | I14: {=_xlfn.IFNA(_xlfn.XLOOKUP(B14&F14,'Activity by Category'!$B$4:$B$99&'Activity by Category'!$C$4:$C$99,'Activity by Category'!$E$4:$E$99)/100,1)} -> 0.69306931 | J14: =I14*_xlfn.XLOOKUP($B14,Inputs!$B$5:$B$9,Inputs!$H$5:$H$9) -> 27.722772 | K14: 0.2 | L14: 0.25 | M14: =$J14*K14 -> 5.5445545 | N14: =$J14*L14 -> 6.9306931 | O14: =M14/$E14 -> 0.13861386 | P14: =N14/$E14 -> 0.17326733 | Q14: =O14*$C14*$D14 -> 474059.41 | R14: =P14*$C14*$D14 -> 592574.26 | S14: 17 | T14: qw
A15: 5 | B15: R+R Pod | C15: =_xlfn.XLOOKUP($B15,Inputs!$B$5:$B$9,Inputs!$D$5:$D$9) -> 43 | D15: =_xlfn.XLOOKUP($B15,Inputs!$B$5:$B$9,Inputs!E$5:E$9) -> 60000 | E15: =_xlfn.XLOOKUP($B15,Inputs!$B$5:$B$9,Inputs!H$5:H$9) -> 40 | F15: Case management and processing | G15: Automation | H15: Provide self-serve channel for customers to initiate R+R | I15: {=_xlfn.IFNA(_xlfn.XLOOKUP(B15&F15,'Activity by Category'!$B$4:$B$99&'Activity by Category'!$C$4:$C$99,'Activity by Category'!$E$4:$E$99)/100,1)} -> 0.66326531 | J15: =I15*_xlfn.XLOOKUP($B15,Inputs!$B$5:$B$9,Inputs!$H$5:$H$9) -> 26.530612 | K15: 0.2 | L15: 0.3 | M15: =$J15*K15 -> 5.3061224 | N15: =$J15*L15 -> 7.9591837 | O15: =M15/$E15 -> 0.13265306 | P15: =N15/$E15 -> 0.19897959 | Q15: =O15*$C15*$D15 -> 342244.9 | R15: =P15*$C15*$D15 -> 513367.35 | S15: 28 | T15: qw
... A22: 4 | B22: Customer Care | C22: =_xlfn.XLOOKUP($B22,Inputs!$B$5:$B$9,Inputs!$D$5:$D$9) -> 21 | D22: =_xlfn.XLOOKUP($B22,Inputs!$B$5:$B$9,Inputs!E$5:E$9) -> 60000 | E22: =_xlfn.XLOOKUP($B22,Inputs!$B$5:$B$9,Inputs!H$5:H$9) -> 40 | F22: Issue resolution | G22: Process | H22: Clarify ownership boundaries between Customer Care, SSRs, and R&R for order tracking and problem resolution | I22: {=_xlfn.IFNA(_xlfn.XLOOKUP(B22&F22,'Activity by Category'!$B$4:$B$99&'Activity by Category'!$C$4:$C$99,'Activity by Category'!$E$4:$E$99)/100,1)} -> 0.85773563 | J22: =I22*_xlfn.XLOOKUP($B22,Inputs!$B$5:$B$9,Inputs!$H$5:$H$9) -> 34.309425 | K22: 0.03 | L22: 0.05 | M22: =$J22*K22 -> 1.0292828 | N22: =$J22*L22 -> 1.7154713 | O22: =M22/$E22 -> 0.025732069 | P22: =N22/$E22 -> 0.042886781 | Q22: =O22*$C22*$D22 -> 32422.407 | R22: =P22*$C22*$D22 -> 54037.344 | S22: 27 | T22: qw
A23: 1 | B23: SSR | C23: =_xlfn.XLOOKUP($B23,Inputs!$B$5:$B$9,Inputs!$D$5:$D$9) -> 188 | D23: =_xlfn.XLOOKUP($B23,Inputs!$B$5:$B$9,Inputs!E$5:E$9) -> 60000 | E23: =_xlfn.XLOOKUP($B23,Inputs!$B$5:$B$9,Inputs!H$5:H$9) -> 40 | F23: Order management | G23: Automation | H23: Implement a self-service channel that allows customers to submit core order change requests and routes them to an approve/reject workflow | I23: {=_xlfn.IFNA(_xlfn.XLOOKUP(B23&F23,'Activity by Category'!$B$4:$B$99&'Activity by Category'!$C$4:$C$99,'Activity by Category'!$E$4:$E$99)/100,1)} -> 0.70454545 | J23: =I23*_xlfn.XLOOKUP($B23,Inputs!$B$5:$B$9,Inputs!$H$5:$H$9) -> 28.181818 | K23: 0.02 | L23: 0.07 | M23: =$J23*K23 -> 0.56363636 | N23: =$J23*L23 -> 1.9727273 | O23: =M23/$E23 -> 0.014090909 | P23: =N23/$E23 -> 0.049318182 | Q23: =O23*$C23*$D23 -> 158945.45 | R23: =P23*$C23*$D23 -> 556309.09 | S23: 4
A24: 1 | B24: SSR | C24: =_xlfn.XLOOKUP($B24,Inputs!$B$5:$B$9,Inputs!$D$5:$D$9) -> 188 | D24: =_xlfn.XLOOKUP($B24,Inputs!$B$5:$B$9,Inputs!E$5:E$9) -> 60000 | E24: =_xlfn.XLOOKUP($B24,Inputs!$B$5:$B$9,Inputs!H$5:H$9) -> 40 | F24: Issue resolution | G24: Automation | H24: Implement smart routing and exception handling to focus reps on complex cases | I24: {=_xlfn.IFNA(_xlfn.XLOOKUP(B24&F24,'Activity by Category'!$B$4:$B$99&'Activity by Category'!$C$4:$C$99,'Activity by Category'!$E$4:$E$99)/100,1)} -> 0.17045455 | J24: =I24*_xlfn.XLOOKUP($B24,Inputs!$B$5:$B$9,Inputs!$H$5:$H$9) -> 6.8181818 | K24: 0.15 | L24: 0.2 | M24: =$J24*K24 -> 1.0227273 | N24: =$J24*L24 -> 1.3636364 | O24: =M24/$E24 -> 0.025568182 | P24: =N24/$E24 -> 0.034090909 | Q24: =O24*$C24*$D24 -> 288409.09 | R24: =P24*$C24*$D24 -> 384545.45 | S24: 6
A25: 2 | B25: TM | C25: =_xlfn.XLOOKUP($B25,Inputs!$B$5:$B$9,Inputs!$D$5:$D$9) -> 139 | D25: =_xlfn.XLOOKUP($B25,Inputs!$B$5:$B$9,Inputs!E$5:E$9) -> 60000 | E25: =_xlfn.XLOOKUP($B25,Inputs!$B$5:$B$9,Inputs!H$5:H$9) -> 40 | F25: Sales support activities | G25: Process | H25: Clarify boundaries between TMs and SSRs for quoting vs. order setup | I25: {=_xlfn.IFNA(_xlfn.XLOOKUP(B25&F25,'Activity by Category'!$B$4:$B$99&'Activity by Category'!$C$4:$C$99,'Activity by Category'!$E$4:$E$99)/100,1)} -> 0.90697674 | J25: =I25*_xlfn.XLOOKUP($B25,Inputs!$B$5:$B$9,Inputs!$H$5:$H$9) -> 36.27907 | K25: 0.02 | L25: 0.03 | M25: =$J25*K25 -> 0.7255814 | N25: =$J25*L25 -> 1.0883721 | O25: =M25/$E25 -> 0.018139535 | P25: =N25/$E25 -> 0.027209302 | Q25: =O25*$C25*$D25 -> 151283.72 | R25: =P25*$C25*$D25 -> 226925.58 | S25: 15
A26: 1 | B26: SSR | C26: =_xlfn.XLOOKUP($B26,Inputs!$B$5:$B$9,Inputs!$D$5:$D$9) -> 188 | D26: =_xlfn.XLOOKUP($B26,Inputs!$B$5:$B$9,Inputs!E$5:E$9) -> 60000 | E26: =_xlfn.XLOOKUP($B26,Inputs!$B$5:$B$9,Inputs!H$5:H$9) -> 40 | F26: Issue resolution | G26: Process | H26: Redesign post-order processes to reduce redundant communication loops and follow-ups | I26: {=_xlfn.IFNA(_xlfn.XLOOKUP(B26&F26,'Activity by Category'!$B$4:$B$99&'Activity by Category'!$C$4:$C$99,'Activity by Category'!$E$4:$E$99)/100,1)} -> 0.17045455 | J26: =I26*_xlfn.XLOOKUP($B26,Inputs!$B$5:$B$9,Inputs!$H$5:$H$9) -> 6.8181818 | K26: 0.05 | L26: 0.1 | M26: =$J26*K26 -> 0.34090909 | N26: =$J26*L26 -> 0.68181818 | O26: =M26/$E26 -> 0.0085227273 | P26: =N26/$E26 -> 0.017045455 | Q26: =O26*$C26*$D26 -> 96136.364 | R26: =P26*$C26*$D26 -> 192272.73 | S26: 8
A27: 3 | B27: MTS Pod | C27: =_xlfn.XLOOKUP($B27,Inputs!$B$5:$B$9,Inputs!$D$5:$D$9) -> 57 | D27: =_xlfn.XLOOKUP($B27,Inputs!$B$5:$B$9,Inputs!E$5:E$9) -> 60000 | E27: =_xlfn.XLOOKUP($B27,Inputs!$B$5:$B$9,Inputs!H$5:H$9) -> 40 | F27: Shop creation | G27: Automation | H27: Streamline artwork submissions and auto-route licensing submissions for approval | I27: {=_xlfn.IFNA(_xlfn.XLOOKUP(B27&F27,'Activity by Category'!$B$4:$B$99&'Activity by Category'!$C$4:$C$99,'Activity by Category'!$E$4:$E$99)/100,1)} -> 0.69306931 | J27: =I27*_xlfn.XLOOKUP($B27,Inputs!$B$5:$B$9,Inputs!$H$5:$H$9) -> 27.722772 | K27: 0.05 | L27: 0.08 | M27: =$J27*K27 -> 1.3861386 | N27: =$J27*L27 -> 2.2178218 | O27: =M27/$E27 -> 0.034653465 | P27: =N27/$E27 -> 0.055445545 | Q27: =O27*$C27*$D27 -> 118514.85 | R27: =P27*$C27*$D27 -> 189623.76 | S27: 19
A28: 5 | B28: R+R Pod | C28: =_xlfn.XLOOKUP($B28,Inputs!$B$5:$B$9,Inputs!$D$5:$D$9) -> 43 | D28: =_xlfn.XLOOKUP($B28,Inputs!$B$5:$B$9,Inputs!E$5:E$9) -> 60000 | E28: =_xlfn.XLOOKUP($B28,Inputs!$B$5:$B$9,Inputs!H$5:H$9) -> 40 | F28: Case management and processing | G28: Automation | H28: Digitally request and receive vendor return authorizations within Engage, removing email dependency | I28: {=_xlfn.IFNA(_xlfn.XLOOKUP(B28&F28,'Activity by Category'!$B$4:$B$99&'Activity by Category'!$C$4:$C$99,'Activity by Category'!$E$4:$E$99)/100,1)} -> 0.66326531 | J28: =I28*_xlfn.XLOOKUP($B28,Inputs!$B$5:$B$9,Inputs!$H$5:$H$9) -> 26.530612 | K28: 0.07 | L28: 0.1 | M28: =$J28*K28 -> 1.8571429 | N28: =$J28*L28 -> 2.6530612 | O28: =M28/$E28 -> 0.046428571 | P28: =N28/$E28 -> 0.066326531 | Q28: =O28*$C28*$D28 -> 119785.71 | R28: =P28*$C28*$D28 -> 171122.45 | S28: 30
A29: 4 | B29: Customer Care | C29: =_xlfn.XLOOKUP($B29,Inputs!$B$5:$B$9,Inputs!$D$5:$D$9) -> 21 | D29: =_xlfn.XLOOKUP($B29,Inputs!$B$5:$B$9,Inputs!E$5:E$9) -> 60000 | E29: =_xlfn.XLOOKUP($B29,Inputs!$B$5:$B$9,Inputs!H$5:H$9) -> 40 | F29: Issue resolution | G29: Automation | H29: Enable customers to resolve common issues with self-service chatbot | I29: {=_xlfn.IFNA(_xlfn.XLOOKUP(B29&F29,'Activity by Category'!$B$4:$B$99&'Activity by Category'!$C$4:$C$99,'Activity by Category'!$E$4:$E$99)/100,1)} -> 0.85773563 | J29: =I29*_xlfn.XLOOKUP($B29,Inputs!$B$5:$B$9,Inputs!$H$5:$H$9) -> 34.309425 | K29: 0.1 | L29: 0.15 | M29: =$J29*K29 -> 3.4309425 | N29: =$J29*L29 -> 5.1464138 | O29: =M29/$E29 -> 0.085773563 | P29: =N29/$E29 -> 0.12866034 | Q29: =O29*$C29*$D29 -> 108074.69 | R29: =P29*$C29*$D29 -> 162112.03 | S29: 23
A30: 3 | B30: MTS Pod | C30: =_xlfn.XLOOKUP($B30,Inputs!$B$5:$B$9,Inputs!$D$5:$D$9) -> 57 | D30: =_xlfn.XLOOKUP($B30,Inputs!$B$5:$B$9,Inputs!E$5:E$9) -> 60000 | E30: =_xlfn.XLOOKUP($B30,Inputs!$B$5:$B$9,Inputs!H$5:H$9) -> 40 | F30: Shop creation support activities | G30: Process | H30: Streamline MTS change requests processes | I30: {=_xlfn.IFNA(_xlfn.XLOOKUP(B30&F30,'Activity by Category'!$B$4:$B$99&'Activity by Category'!$C$4:$C$99,'Activity by Category'!$E$4:$E$99)/100,1)} -> 0.15841584 | J30: =I30*_xlfn.XLOOKUP($B30,Inputs!$B$5:$B$9,Inputs!$H$5:$H$9) -> 6.3366337 | K30: 0.1 | L30: 0.2 | M30: =$J30*K30 -> 0.63366337 | N30: =$J30*L30 -> 1.2673267 | O30: =M30/$E30 -> 0.015841584 | P30: =N30/$E30 -> 0.031683168 | Q30: =O30*$C30*$D30 -> 54178.218 | R30: =P30*$C30*$D30 -> 108356.44 | S30: 20
A31: 4 | B31: Customer Care | C31: =_xlfn.XLOOKUP($B31,Inputs!$B$5:$B$9,Inputs!$D$5:$D$9) -> 21 | D31: =_xlfn.XLOOKUP($B31,Inputs!$B$5:$B$9,Inputs!E$5:E$9) -> 60000 | E31: =_xlfn.XLOOKUP($B31,Inputs!$B$5:$B$9,Inputs!H$5:H$9) -> 40 | F31: Issue resolution | G31: Automation | H31: Utilize intelligent ticket routing to assign customer issues to the right queue or specialist | I31: {=_xlfn.IFNA(_xlfn.XLOOKUP(B31&F31,'Activity by Category'!$B$4:$B$99&'Activity by Category'!$C$4:$C$99,'Activity by Category'!$E$4:$E$99)/100,1)} -> 0.85773563 | J31: =I31*_xlfn.XLOOKUP($B31,Inputs!$B$5:$B$9,Inputs!$H$5:$H$9) -> 34.309425 | K31: 0.05 | L31: 0.1 | M31: =$J31*K31 -> 1.7154713 | N31: =$J31*L31 -> 3.4309425 | O31: =M31/$E31 -> 0.042886781 | P31: =N31/$E31 -> 0.085773563 | Q31: =O31*$C31*$D31 -> 54037.344 | R31: =P31*$C31*$D31 -> 108074.69 | S31: 24
A32: 4 | B32: Customer Care | C32: =_xlfn.XLOOKUP($B32,Inputs!$B$5:$B$9,Inputs!$D$5:$D$9) -> 21 | D32: =_xlfn.XLOOKUP($B32,Inputs!$B$5:$B$9,Inputs!E$5:E$9) -> 60000 | E32: =_xlfn.XLOOKUP($B32,Inputs!$B$5:$B$9,Inputs!H$5:H$9) -> 40 | F32: Issue resolution | G32: Automation | H32: Streamline ticket generation follow-ups and other post-call activities | I32: {=_xlfn.IFNA(_xlfn.XLOOKUP(B32&F32,'Activity by Category'!$B$4:$B$99&'Activity by Category'!$C$4:$C$99,'Activity by Category'!$E$4:$E$99)/100,1)} -> 0.85773563 | J32: =I32*_xlfn.XLOOKUP($B32,Inputs!$B$5:$B$9,Inputs!$H$5:$H$9) -> 34.309425 | K32: 0.05 | L32: 0.1 | M32: =$J32*K32 -> 1.7154713 | N32: =$J32*L32 -> 3.4309425 | O32: =M32/$E32 -> 0.042886781 | P32: =N32/$E32 -> 0.085773563 | Q32: =O32*$C32*$D32 -> 54037.344 | R32: =P32*$C32*$D32 -> 108074.69 | S32: 25
A33: 5 | B33: R+R Pod | C33: =_xlfn.XLOOKUP($B33,Inputs!$B$5:$B$9,Inputs!$D$5:$D$9) -> 43 | D33: =_xlfn.XLOOKUP($B33,Inputs!$B$5:$B$9,Inputs!E$5:E$9) -> 60000 | E33: =_xlfn.XLOOKUP($B33,Inputs!$B$5:$B$9,Inputs!H$5:H$9) -> 40 | F33: Case management and processing | G33: Process | H33: Implement standardized intake checklist for new cases | I33: {=_xlfn.IFNA(_xlfn.XLOOKUP(B33&F33,'Activity by Category'!$B$4:$B$99&'Activity by Category'!$C$4:$C$99,'Activity by Category'!$E$4:$E$99)/100,1)} -> 0.66326531 | J33: =I33*_xlfn.XLOOKUP($B33,Inputs!$B$5:$B$9,Inputs!$H$5:$H$9) -> 26.530612 | K33: 0.04 | L33: 0.06 | M33: =$J33*K33 -> 1.0612245 | N33: =$J33*L33 -> 1.5918367 | O33: =M33/$E33 -> 0.026530612 | P33: =N33/$E33 -> 0.039795918 | Q33: =O33*$C33*$D33 -> 68448.98 | R33: =P33*$C33*$D33 -> 102673.47 | S33: 31
A34: 3 | B34: MTS Pod | C34: =_xlfn.XLOOKUP($B34,Inputs!$B$5:$B$9,Inputs!$D$5:$D$9) -> 57 | D34: =_xlfn.XLOOKUP($B34,Inputs!$B$5:$B$9,Inputs!E$5:E$9) -> 60000 | E34: =_xlfn.XLOOKUP($B34,Inputs!$B$5:$B$9,Inputs!H$5:H$9) -> 40 | F34: Shop creation | G34: Process | H34: Streamline QC and standardize review process to minimize rework | I34: {=_xlfn.IFNA(_xlfn.XLOOKUP(B34&F34,'Activity by Category'!$B$4:$B$99&'Activity by Category'!$C$4:$C$99,'Activity by Category'!$E$4:$E$99)/100,1)} -> 0.69306931 | J34: =I34*_xlfn.XLOOKUP($B34,Inputs!$B$5:$B$9,Inputs!$H$5:$H$9) -> 27.722772 | K34: 0.02 | L34: 0.03 | M34: =$J34*K34 -> 0.55445545 | N34: =$J34*L34 -> 0.83168317 | O34: =M34/$E34 -> 0.013861386 | P34: =N34/$E34 -> 0.020792079 | Q34: =O34*$C34*$D34 -> 47405.941 | R34: =P34*$C34*$D34 -> 71108.911 | S34: 21
... A36: 5 | B36: R+R Pod | C36: =_xlfn.XLOOKUP($B36,Inputs!$B$5:$B$9,Inputs!$D$5:$D$9) -> 43 | D36: =_xlfn.XLOOKUP($B36,Inputs!$B$5:$B$9,Inputs!E$5:E$9) -> 60000 | E36: =_xlfn.XLOOKUP($B36,Inputs!$B$5:$B$9,Inputs!H$5:H$9) -> 40 | F36: Communication & coordination | G36: Process | H36: Standardize and schedule reminder templates for vendor follow-ups (e.g., pending return authorization, missing info) | I36: {=_xlfn.IFNA(_xlfn.XLOOKUP(B36&F36,'Activity by Category'!$B$4:$B$99&'Activity by Category'!$C$4:$C$99,'Activity by Category'!$E$4:$E$99)/100,1)} -> 0.20408163 | J36: =I36*_xlfn.XLOOKUP($B36,Inputs!$B$5:$B$9,Inputs!$H$5:$H$9) -> 8.1632653 | K36: 0.04 | L36: 0.06 | M36: =$J36*K36 -> 0.32653061 | N36: =$J36*L36 -> 0.48979592 | O36: =M36/$E36 -> 0.0081632653 | P36: =N36/$E36 -> 0.012244898 | Q36: =O36*$C36*$D36 -> 21061.224 | R36: =P36*$C36*$D36 -> 31591.837 | S36: 33

Sheet temp2
B3: Role | C3: FTEs for ROLE | D3: Cost per year for ROLE | E3: Total hours per week for ROLE | F3: Archetype | G3: Category of opportunity | H3: Opportunity description | I3: Current time spent on activity category (%) | J3: Current time spent on activity archetype (hrs per week) | K3: Efficiency gained on activity archetype % (low-end) | L3: Efficiency gained on activity archetype % (high-end) | M3: Hours saved (low-end) | N3: Hours saved (high-end) | O3: Efficiency gained % on total workweek (low-end) | P3: Efficiency gained % on total workweek (high-end) | Q3: $ impact (low-end) | R3: $ impact (high-end)
B4: R+R Pod | C4: =_xlfn.XLOOKUP($B4,Inputs!$B$5:$B$9,Inputs!$C$5:$C$9) -> 48 | D4: =_xlfn.XLOOKUP($B4,Inputs!$B$5:$B$9,Inputs!I$5:I$9) -> 56875 | E4: =_xlfn.XLOOKUP($B4,Inputs!$B$5:$B$9,Inputs!H$5:H$9) -> 40 | F4: Communication & coordination | G4: Process | H4: Standardize and schedule reminder templates for vendor follow-ups (e.g., pending return authorization, missing info) | I4: {=_xlfn.IFNA(_xlfn.XLOOKUP(B4&F4,'Activity by Category'!$B$4:$B$99&'Activity by Category'!$C$4:$C$99,'Activity by Category'!$E$4:$E$99)/100,1)} -> 0.20408163 | J4: =I4*_xlfn.XLOOKUP($B4,Inputs!$B$5:$B$9,Inputs!$H$5:$H$9) -> 8.1632653 | K4: 0.04 | L4: 0.06 | M4: =$J4*K4 -> 0.32653061 | N4: =$J4*L4 -> 0.48979592 | O4: =M4/$E4 -> 0.0081632653 | P4: =N4/$E4 -> 0.012244898 | Q4: =O4*$C4*$D4 -> 22285.714 | R4: =P4*$C4*$D4 -> 33428.571
B5: R+R Pod | C5: =_xlfn.XLOOKUP($B5,Inputs!$B$5:$B$9,Inputs!$C$5:$C$9) -> 48 | D5: =_xlfn.XLOOKUP($B5,Inputs!$B$5:$B$9,Inputs!I$5:I$9) -> 56875 | E5: =_xlfn.XLOOKUP($B5,Inputs!$B$5:$B$9,Inputs!H$5:H$9) -> 40 | F5: Communication & coordination | G5: Automation | H5: Send automatic updates at major status milestones (e.g., “Return received,” “Replacement shipped,” “Credit applied”). | I5: {=_xlfn.IFNA(_xlfn.XLOOKUP(B5&F5,'Activity by Category'!$B$4:$B$99&'Activity by Category'!$C$4:$C$99,'Activity by Category'!$E$4:$E$99)/100,1)} -> 0.20408163 | J5: =I5*_xlfn.XLOOKUP($B5,Inputs!$B$5:$B$9,Inputs!$H$5:$H$9) -> 8.1632653 | K5: 0.05 | L5: 0.08 | M5: =$J5*K5 -> 0.40816327 | N5: =$J5*L5 -> 0.65306122 | O5: =M5/$E5 -> 0.010204082 | P5: =N5/$E5 -> 0.016326531 | Q5: =O5*$C5*$D5 -> 27857.143 | R5: =P5*$C5*$D5 -> 44571.429
B6: R+R Pod | C6: =_xlfn.XLOOKUP($B6,Inputs!$B$5:$B$9,Inputs!$C$5:$C$9) -> 48 | D6: =_xlfn.XLOOKUP($B6,Inputs!$B$5:$B$9,Inputs!I$5:I$9) -> 56875 | E6: =_xlfn.XLOOKUP($B6,Inputs!$B$5:$B$9,Inputs!H$5:H$9) -> 40 | F6: Case management and processing | G6: Process | H6: Implement standardized intake checklist for new cases | I6: {=_xlfn.IFNA(_xlfn.XLOOKUP(B6&F6,'Activity by Category'!$B$4:$B$99&'Activity by Category'!$C$4:$C$99,'Activity by Category'!$E$4:$E$99)/100,1)} -> 0.66326531 | J6: =I6*_xlfn.XLOOKUP($B6,Inputs!$B$5:$B$9,Inputs!$H$5:$H$9) -> 26.530612 | K6: 0.04 | L6: 0.06 | M6: =$J6*K6 -> 1.0612245 | N6: =$J6*L6 -> 1.5918367 | O6: =M6/$E6 -> 0.026530612 | P6: =N6/$E6 -> 0.039795918 | Q6: =O6*$C6*$D6 -> 72428.571 | R6: =P6*$C6*$D6 -> 108642.86
B7: MTS Pod | C7: =_xlfn.XLOOKUP($B7,Inputs!$B$5:$B$9,Inputs!$C$5:$C$9) -> 73 | D7: =_xlfn.XLOOKUP($B7,Inputs!$B$5:$B$9,Inputs!I$5:I$9) -> 53424.658 | E7: =_xlfn.XLOOKUP($B7,Inputs!$B$5:$B$9,Inputs!H$5:H$9) -> 40 | F7: Shop creation | G7: Process | H7: Streamline QC and standardize review process to minimize rework | I7: {=_xlfn.IFNA(_xlfn.XLOOKUP(B7&F7,'Activity by Category'!$B$4:$B$99&'Activity by Category'!$C$4:$C$99,'Activity by Category'!$E$4:$E$99)/100,1)} -> 0.69306931 | J7: =I7*_xlfn.XLOOKUP($B7,Inputs!$B$5:$B$9,Inputs!$H$5:$H$9) -> 27.722772 | K7: 0.02 | L7: 0.03 | M7: =$J7*K7 -> 0.55445545 | N7: =$J7*L7 -> 0.83168317 | O7: =M7/$E7 -> 0.013861386 | P7: =N7/$E7 -> 0.020792079 | Q7: =O7*$C7*$D7 -> 54059.406 | R7: =P7*$C7*$D7 -> 81089.109
B8: Customer Care | C8: =_xlfn.XLOOKUP($B8,Inputs!$B$5:$B$9,Inputs!$C$5:$C$9) -> 51 | D8: =_xlfn.XLOOKUP($B8,Inputs!$B$5:$B$9,Inputs!I$5:I$9) -> 42352.941 | E8: =_xlfn.XLOOKUP($B8,Inputs!$B$5:$B$9,Inputs!H$5:H$9) -> 40 | F8: Issue resolution | G8: Process | H8: Define structured communication templates (email and Engage) to ensure consistent customer messaging | I8: {=_xlfn.IFNA(_xlfn.XLOOKUP(B8&F8,'Activity by Category'!$B$4:$B$99&'Activity by Category'!$C$4:$C$99,'Activity by Category'!$E$4:$E$99)/100,1)} -> 0.85773563 | J8: =I8*_xlfn.XLOOKUP($B8,Inputs!$B$5:$B$9,Inputs!$H$5:$H$9) -> 34.309425 | K8: 0.03 | L8: 0.05 | M8: =$J8*K8 -> 1.0292828 | N8: =$J8*L8 -> 1.7154713 | O8: =M8/$E8 -> 0.025732069 | P8: =N8/$E8 -> 0.042886781 | Q8: =O8*$C8*$D8 -> 55581.269 | R8: =P8*$C8*$D8 -> 92635.448
B9: Customer Care | C9: =_xlfn.XLOOKUP($B9,Inputs!$B$5:$B$9,Inputs!$C$5:$C$9) -> 51 | D9: =_xlfn.XLOOKUP($B9,Inputs!$B$5:$B$9,Inputs!I$5:I$9) -> 42352.941 | E9: =_xlfn.XLOOKUP($B9,Inputs!$B$5:$B$9,Inputs!H$5:H$9) -> 40 | F9: Issue resolution | G9: Process | H9: Clarify ownership boundaries between Customer Care, SSRs, and R&R for order tracking and problem resolution | I9: {=_xlfn.IFNA(_xlfn.XLOOKUP(B9&F9,'Activity by Category'!$B$4:$B$99&'Activity by Category'!$C$4:$C$99,'Activity by Category'!$E$4:$E$99)/100,1)} -> 0.85773563 | J9: =I9*_xlfn.XLOOKUP($B9,Inputs!$B$5:$B$9,Inputs!$H$5:$H$9) -> 34.309425 | K9: 0.03 | L9: 0.05 | M9: =$J9*K9 -> 1.0292828 | N9: =$J9*L9 -> 1.7154713 | O9: =M9/$E9 -> 0.025732069 | P9: =N9/$E9 -> 0.042886781 | Q9: =O9*$C9*$D9 -> 55581.269 | R9: =P9*$C9*$D9 -> 92635.448
